Workbook

Sheet Receipt
B2: RECEIPT STATEMENT AS ON TODAY.
B3: INWORD | N3: OUTWORD
B4: TYPES | C4: DC NO | D4: DATE | E4: L.R. NO | F4: DATE | G4: TRANSPORTER | H4: REC.DATE | I4: Total Boxes | J4: Box * Qty | K4: QTY (in Nos) | L4: RATE | M4: BASIC VALUE | N4: W/H INVOICE NO | O4: DATE | P4: Total Boxes | Q4: Box * Qty | R4: QTY Lifted | S4: DATE | T4: BAL.QTY
B5: OM6004D8 | C5: 305 | D5: 46203 | E5: 12850 | F5: 46203 | G5: SP ROADLINES | H5: 46209 | I5: 1 | J5: 1*3400 | K5: =1*3400 -> 3400 | L5: 10.03 | M5: =+K5*L5 -> 34102 | S5: P | T5: =+K5-R5 -> 3400
B6: OM6004D8 | C6: 321 | D6: 46206 | E6: 12875 | F6: 46206 | G6: SP ROADLINES | H6: 46212 | I6: 2 | J6: 2*6000 | K6: =2*6000 -> 12000 | L6: 10.03 | M6: =+K6*L6 -> 120360 | S6: P | T6: =+K6-R6 -> 12000
B7: OM6004D8 | C7: 336 | D7: 46209 | E7: 12901 | F7: 46209 | G7: SP ROADLINES | H7: 46212 | I7: 2 | J7: 2*6000 | K7: =2*6000 -> 12000 | L7: 10.03 | M7: =+K7*L7 -> 120360 | S7: P | T7: =+K7-R7 -> 12000
B8: OM6004D8 | C8: 350 | D8: 46212 | E8: 12915 | F8: 46212 | G8: SP ROADLINES | H8: 46217 | I8: 1 | J8: 1*6000 | K8: =1*6000 -> 6000 | L8: 10.03 | M8: =+K8*L8 -> 60180 | S8: P | T8: =+K8-R8 -> 6000
B9: OM6004D8 | C9: 360 | D9: 46212 | E9: 12915 | F9: 46212 | G9: SP ROADLINES | H9: 46217 | I9: 1 | J9: 1*6000 | K9: =1*6000 -> 6000 | L9: 10.03 | M9: =+K9*L9 -> 60180 | S9: P | T9: =+K9-R9 -> 6000
B10: OM6004D8 | C10: 411 | D10: 46225 | E10: 12986 | F10: 46225 | G10: SP ROADLINES | H10: 46230 | I10: 1 | J10: 1*6000 | K10: =1*6000 -> 6000 | L10: 10.03 | M10: =+K10*L10 -> 60180 | S10: P | T10: =+K10-R10 -> 6000
B11: OM6004D8 | C11: 420 | D11: 46228 | E11: 12996 | F11: 46228 | G11: SP ROADLINES | H11: 46231 | I11: 1 | J11: 1*6000 | K11: =1*6000 -> 6000 | L11: 10.03 | M11: =+K11*L11 -> 60180 | S11: P | T11: =+K11-R11 -> 6000
B12: OM6004D8 | C12: 460 | D12: 46238 | E12: 13053 | F12: 46238 | G12: SP ROADLINES | H12: 46242 | I12: 1 | J12: 1*6000 | K12: =1*6000 -> 6000 | L12: 10.03 | M12: =+K12*L12 -> 60180 | S12: P | T12: =+K12-R12 -> 6000
B13: OM6004D8 | C13: 474 | D13: 46242 | E13: 13068 | F13: 46242 | G13: SP ROADLINES | H13: 46247 | I13: 3 | J13: 3*6000 | K13: =3*6000 -> 18000 | L13: 10.03 | M13: =+K13*L13 -> 180540 | S13: P | T13: =+K13-R13 -> 18000
B14: OM6004D8 | C14: 487 | D14: 46243 | E14: 13068 | F14: 46243 | G14: SP ROADLINES | H14: 46247 | I14: 1 | J14: 1*6000 | K14: =1*6000 -> 6000 | L14: 10.03 | M14: =+K14*L14 -> 60180 | S14: P | T14: =+K14-R14 -> 6000
B15: OM6004D8 | C15: 491 | D15: 46246 | E15: 13084 | F15: 46246 | G15: SP ROADLINES | H15: 46252 | I15: 2 | J15: 2*6000 | K15: =2*6000 -> 12000 | L15: 10.03 | M15: =+K15*L15 -> 120360 | S15: P | T15: =+K15-R15 -> 12000
B16: OM6004D8 | C16: 503 | D16: 46251 | E16: 13105 | F16: 46251 | G16: SP ROADLINES | H16: 46255 | I16: 1 | J16: 1*5500 | K16: =1*5500 -> 5500 | L16: 10.03 | M16: =+K16*L16 -> 55165 | S16: P | T16: =+K16-R16 -> 5500
B17: OM6004D8 | C17: 517 | D17: 46255 | E17: 13132 | F17: 46255 | G17: SP ROADLINES | H17: 46260 | I17: 3 | J17: 3*6000 | K17: =3*6000 -> 18000 | L17: 10.03 | M17: =+K17*L17 -> 180540 | S17: P | T17: =+K17-R17 -> 18000
B18: OM6004D8 | C18: 527 | D18: 46258 | E18: 13150 | F18: 46258 | G18: SP ROADLINES | H18: 46262 | I18: 1 | J18: 1*6000 | K18: =1*6000 -> 6000 | L18: 10.03 | M18: =+K18*L18 -> 60180 | S18: P | T18: =+K18-R18 -> 6000
B20: Total | I20: =SUM(I5:I19) -> 21 | K20: =SUM(K5:K19) -> 122900 | M20: =SUM(M5:M19) -> 1232687 | R20: =SUM(R5:R19) -> 0 | T20: =SUM(T5:T19) -> 122900
B21: OM6004 | C21: 554 | D21: 46265 | E21: 13180 | F21: 46265 | G21: SP ROADLINES | H21: 46270 | I21: 1 | J21: 1*6000 | K21: =1*6000 -> 6000 | L21: 10.23 | M21: =+K21*L21 -> 61380 | S21: P | T21: =+K21-R21 -> 6000
B22: OM6004 | C22: 546 | D22: 46265 | E22: 13180 | F22: 46265 | G22: SP ROADLINES | H22: 46270 | I22: 1 | J22: 1*6000 | K22: =1*6000 -> 6000 | L22: 10.23 | M22: =+K22*L22 -> 61380 | S22: P | T22: =+K22-R22 -> 6000
B24: Total | I24: =SUM(I21:I23) -> 2 | K24: =SUM(K21:K23) -> 12000 | M24: =SUM(M21:M23) -> 122760 | R24: =SUM(R21:R23) -> 0 | T24: =SUM(T21:T23) -> 12000
B25: IM6004 | C25: 488 | D25: 46243 | E25: 13068 | F25: 46243 | G25: SP ROADLINES | H25: 46247 | I25: 5 | J25: 5*1000 | K25: =5*1000 -> 5000 | L25: 7.27 | M25: =+K25*L25 -> 36350 | S25: P | T25: =+K25-R25 -> 5000
B26: IM6004 | C26: 492 | D26: 46246 | E26: 13084 | F26: 46246 | G26: SP ROADLINES | H26: 46252 | I26: 1 | J26: 1*12000 | K26: =1*12000 -> 12000 | L26: 7.27 | M26: =+K26*L26 -> 87240 | S26: P | T26: =+K26-R26 -> 12000
B27: IM6004 | C27: 547 | D27: 46265 | E27: 13180 | F27: 46265 | G27: SP ROADLINES | H27: 46270 | I27: 1 | J27: 1*12000 | K27: =1*12000 -> 12000 | L27: 7.27 | M27: =+K27*L27 -> 87240 | S27: P | T27: =+K27-R27 -> 12000
B29: Total | I29: =SUM(I25:I28) -> 7 | K29: =SUM(K25:K28) -> 29000 | M29: =ROUND(SUM(M25:M28),0) -> 210830 | R29: =SUM(R25:R28) -> 0 | T29: =SUM(T25:T28) -> 29000
B30: OM6005 | C30: 557 | D30: 46265 | E30: 13180 | F30: 46265 | G30: SP ROADLINES | H30: 46270 | I30: 1 | J30: 1*5000 | K30: =1*5000 -> 5000 | L30: 10.9 | M30: =+K30*L30 -> 54500 | S30: P | T30: =+K30-R30 -> 5000
B31: OM6005 | C31: 548 | D31: 46265 | E31: 13180 | F31: 46265 | G31: SP ROADLINES | H31: 46270 | I31: 3 | J31: 3*5000 | K31: =3*5000 -> 15000 | L31: 10.9 | M31: =+K31*L31 -> 163500 | S31: P | T31: =+K31-R31 -> 15000
B33: Total | I33: =SUM(I30:I32) -> 4 | K33: =SUM(K30:K32) -> 20000 | M33: =SUM(M30:M32) -> 218000 | R33: =SUM(R30:R32) -> 0 | T33: =SUM(T30:T32) -> 20000
B34: IM6005 | C34: 522 | D34: 46255 | E34: 13132 | F34: 46255 | G34: SP ROADLINES | H34: 46260 | I34: =2+1-2 -> 1 | J34: 1*9000 | K34: =2*10000+1*9000-20000 -> 9000 | L34: 8.16 | M34: =+K34*L34 -> 73440 | S34: P | T34: =+K34-R34 -> 9000
B35: IM6005 | C35: 532 | D35: 46258 | E35: 13150 | F35: 46258 | G35: SP ROADLINES | H35: 46262 | I35: 1 | J35: 1*10000 | K35: =1*10000 -> 10000 | L35: 8.16 | M35: =+K35*L35 -> 81600 | S35: P | T35: =+K35-R35 -> 10000
B36: IM6005 | C36: 538 | D36: 46260 | E36: 13158 | F36: 46260 | G36: SP ROADLINES | H36: 46262 | I36: 1 | J36: 1*10000 | K36: =1*10000 -> 10000 | L36: 8.16 | M36: =+K36*L36 -> 81600 | S36: P | T36: =+K36-R36 -> 10000
B37: IM6005 | C37: 558 | D37: 46265 | E37: 13180 | F37: 46265 | G37: SP ROADLINES | H37: 46270 | I37: 1 | J37: 1*10000 | K37: =1*10000 -> 10000 | L37: 8.16 | M37: =+K37*L37 -> 81600 | S37: P | T37: =+K37-R37 -> 10000
B38: IM6005 | C38: 549 | D38: 46265 | E38: 13180 | F38: 46265 | G38: SP ROADLINES | H38: 46270 | I38: 1 | J38: 1*10000 | K38: =1*10000 -> 10000 | L38: 8.16 | M38: =+K38*L38 -> 81600 | S38: P | T38: =+K38-R38 -> 10000
B40: Total | I40: =SUM(I34:I39) -> 5 | K40: =SUM(K34:K39) -> 49000 | M40: =ROUND(SUM(M34:M39),0) -> 399840 | R40: =SUM(R34:R39) -> 0 | T40: =SUM(T34:T39) -> 49000
B41: OM6302 | C41: 555 | D41: 46265 | E41: 13180 | F41: 46265 | G41: SP ROADLINES | H41: 46270 | I41: 1 | J41: 1*6000 | K41: =1*6000 -> 6000 | L41: 11.3 | M41: =+K41*L41 -> 67800 | S41: P | T41: =+K41-R41 -> 6000
B42: OM6302 | C42: 550 | D42: 46265 | E42: 13180 | F42: 46265 | G42: SP ROADLINES | H42: 46270 | I42: 2 | J42: 2*6000 | K42: =2*6000 -> 12000 | L42: 11.3 | M42: =+K42*L42 -> 135600 | S42: P | T42: =+K42-R42 -> 12000
B44: Total | I44: =SUM(I41:I43) -> 3 | K44: =SUM(K41:K43) -> 18000 | M44: =ROUND(SUM(M41:M43),0) -> 203400 | R44: =SUM(R41:R43) -> 0 | T44: =SUM(T41:T43) -> 18000
B45: IM6302 | C45: 556 | D45: 46260 | E45: 13180 | F45: 46265 | G45: SP ROADLINES | H45: 46270 | I45: 1 | J45: 1*12000 | K45: =1*12000 -> 12000 | L45: 7.62 | M45: =+K45*L45 -> 91440 | O45: 46270 | P45: 1 | Q45: 1*12000 | R45: =1*12000 -> 12000 | S45: 46270 | T45: =+K45-R45 -> 0
B47: Total | I47: =SUM(I45:I46) -> 1 | K47: =SUM(K45:K46) -> 12000 | M47: =ROUND(SUM(M45:M46),0) -> 91440 | R47: =SUM(R45:R46) -> 12000 | T47: =SUM(T45:T46) -> 0
B48: IM6302HSL | C48: 495 | D48: 46246 | E48: 13084 | F48: 46246 | G48: SP ROADLINES | H48: 46252 | I48: 1 | J48: 1*1500 | K48: =1*1500 -> 1500 | L48: 7.82 | M48: =+K48*L48 -> 11730 | S48: P | T48: =+K48-R48 -> 1500
...

Sheet Type Wise Stock
B2: Aashita Enter Stock as on
O3: =+NOW() -> 46270.528 | P3: =+NOW() -> 46270.528
B4: TYPES | C4: DC NO | D4: DATE | E4: L.R. NO | F4: DATE | G4: TRANSPORTER | H4: REC.DATE | I4: Total Boxes | J4: Box * Qty | K4: QTY (in Nos) | L4: RATE | M4: Basic Value | N4: Heat No | P4: Age of Days | R4: Remarks
B5: OM6004D8 | C5: 305 | D5: 46203 | E5: 12850 | F5: 46203 | G5: SP ROADLINES | H5: 46209 | I5: 1 | J5: 1*3400 | K5: 3400 | L5: 10.03 | M5: =+K5*L5 -> 34102 | N5: 250101209 | O5: =$O$3-D5 -> 67.528472 | P5: =$P$3-H5 -> 61.528472
B6: OM6004D8 | C6: 321 | D6: 46206 | E6: 12875 | F6: 46206 | G6: SP ROADLINES | H6: 46212 | I6: 2 | J6: 2*6000 | K6: =2*6000 -> 12000 | L6: 10.03 | M6: =+K6*L6 -> 120360 | N6: 250101209 | O6: =$O$3-D6 -> 64.528472 | P6: =$P$3-H6 -> 58.528472
B7: OM6004D8 | C7: 336 | D7: 46209 | E7: 12901 | F7: 46209 | G7: SP ROADLINES | H7: 46212 | I7: 2 | J7: 2*6000 | K7: =2*6000 -> 12000 | L7: 10.03 | M7: =+K7*L7 -> 120360 | N7: 250101209 | O7: =$O$3-D7 -> 61.528472 | P7: =$P$3-H7 -> 58.528472
B8: OM6004D8 | C8: 350 | D8: 46212 | E8: 12915 | F8: 46212 | G8: SP ROADLINES | H8: 46217 | I8: 1 | J8: 1*6000 | K8: =1*6000 -> 6000 | L8: 10.03 | M8: =+K8*L8 -> 60180 | N8: 250101209 | O8: =$O$3-D8 -> 58.528472 | P8: =$P$3-H8 -> 53.528472
B9: OM6004D8 | C9: 360 | D9: 46212 | E9: 12915 | F9: 46212 | G9: SP ROADLINES | H9: 46217 | I9: 1 | J9: 1*6000 | K9: =1*6000 -> 6000 | L9: 10.03 | M9: =+K9*L9 -> 60180 | N9: 250101209 | O9: =$O$3-D9 -> 58.528472 | P9: =$P$3-H9 -> 53.528472
B10: OM6004D8 | C10: 411 | D10: 46225 | E10: 12986 | F10: 46225 | G10: SP ROADLINES | H10: 46230 | I10: 1 | J10: 1*6000 | K10: =1*6000 -> 6000 | L10: 10.03 | M10: =+K10*L10 -> 60180 | N10: 250101209 | O10: =$O$3-D10 -> 45.528472 | P10: =$P$3-H10 -> 40.528472
B11: OM6004D8 | C11: 420 | D11: 46228 | E11: 12996 | F11: 46228 | G11: SP ROADLINES | H11: 46231 | I11: 1 | J11: 1*6000 | K11: =1*6000 -> 6000 | L11: 10.03 | M11: =+K11*L11 -> 60180 | N11: 250101209 | O11: =$O$3-D11 -> 42.528472 | P11: =$P$3-H11 -> 39.528472
B12: OM6004D8 | C12: 460 | D12: 46238 | E12: 13053 | F12: 46238 | G12: SP ROADLINES | H12: 46242 | I12: 1 | J12: 1*6000 | K12: 6000 | L12: 10.03 | M12: =+K12*L12 -> 60180 | N12: 250101209 | O12: =$O$3-D12 -> 32.528472 | P12: =$P$3-H12 -> 28.528472
B13: OM6004D8 | C13: 474 | D13: 46242 | E13: 13068 | F13: 46242 | G13: SP ROADLINES | H13: 46247 | I13: 3 | J13: 3*6000 | K13: =3*6000 -> 18000 | L13: 10.03 | M13: =+K13*L13 -> 180540 | N13: 260100625 | O13: =$O$3-D13 -> 28.528472 | P13: =$P$3-H13 -> 23.528472
B14: OM6004D8 | C14: 487 | D14: 46243 | E14: 13068 | F14: 46243 | G14: SP ROADLINES | H14: 46247 | I14: 1 | J14: 1*6000 | K14: =1*6000 -> 6000 | L14: 10.03 | M14: =+K14*L14 -> 60180 | N14: 260100625 | O14: =$O$3-D14 -> 27.528472 | P14: =$P$3-H14 -> 23.528472
B15: OM6004D8 | C15: 491 | D15: 46246 | E15: 13084 | F15: 46246 | G15: SP ROADLINES | H15: 46252 | I15: 2 | J15: 2*6000 | K15: =2*6000 -> 12000 | L15: 10.03 | M15: =+K15*L15 -> 120360 | N15: 260100625 | O15: =$O$3-D15 -> 24.528472 | P15: =$P$3-H15 -> 18.528472
B16: OM6004D8 | C16: 503 | D16: 46251 | E16: 13105 | F16: 46251 | G16: SP ROADLINES | H16: 46255 | I16: 1 | J16: 1*5500 | K16: =1*5500 -> 5500 | L16: 10.03 | M16: =+K16*L16 -> 55165 | N16: 260100625 | O16: 4.7676325 | P16: =$O$3-H16 -> 15.528472
B17: OM6004D8 | C17: 517 | D17: 46255 | E17: 13132 | F17: 46255 | G17: SP ROADLINES | H17: 46260 | I17: 3 | J17: 3*6000 | K17: =3*6000 -> 18000 | L17: 10.03 | M17: =+K17*L17 -> 180540 | N17: 260100625 | O17: 4.7676325 | P17: =$O$3-H17 -> 10.528472
B18: OM6004D8 | C18: 527 | D18: 46258 | E18: - | F18: 46258 | G18: SP ROADLINES | H18: 46262 | I18: 1 | J18: 1*6000 | K18: =1*6000 -> 6000 | L18: 10.03 | M18: =+K18*L18 -> 60180 | N18: 260100625 | O18: 4.7676325 | P18: =$O$3-H18 -> 8.5284715
B20: Total | I20: =SUM(I5:I19) -> 21 | K20: =SUM(K5:K19) -> 122900 | M20: =SUM(M5:M19) -> 1232687
B21: OM6004 | C21: 554 | D21: 46265 | E21: 13180 | F21: 46265 | G21: SP ROADLINES | H21: 46270 | I21: 1 | J21: 1*6000 | K21: =1*6000 -> 6000 | L21: 10.23 | M21: =+K21*L21 -> 61380 | N21: 260100625 | O21: =$O$3-D21 -> 5.5284715 | P21: =$O$3-H21 -> 0.52847153
B22: OM6004 | C22: 546 | D22: 46265 | E22: 13180 | F22: 46265 | G22: SP ROADLINES | H22: 46270 | I22: 1 | J22: 1*6000 | K22: =1*6000 -> 6000 | L22: 10.23 | M22: =+K22*L22 -> 61380 | N22: 260100625 | O22: =$O$3-D22 -> 5.5284715 | P22: =$O$3-H22 -> 0.52847153
B24: Total | I24: =SUM(I21:I23) -> 2 | K24: =SUM(K21:K23) -> 12000 | M24: =SUM(M21:M23) -> 122760
B25: IM6004 | C25: 488 | D25: 46243 | E25: 13068 | F25: 46243 | G25: SP ROADLINES | H25: 46247 | I25: 5 | J25: 5*1000 | K25: =5*1000 -> 5000 | L25: 7.27 | M25: =+K25*L25 -> 36350 | N25: 260100623 | O25: =$O$3-D25 -> 27.528472 | P25: =$P$3-H25 -> 23.528472
B26: IM6004 | C26: 492 | D26: 46246 | E26: 13084 | F26: 46246 | G26: SP ROADLINES | H26: 46252 | I26: 1 | J26: 1*12000 | K26: =1*12000 -> 12000 | L26: 7.27 | M26: =+K26*L26 -> 87240 | N26: 260100623 | O26: =$O$3-D26 -> 24.528472 | P26: =$P$3-H26 -> 18.528472
B27: IM6004 | C27: 547 | D27: 46265 | E27: 13180 | F27: 46265 | G27: SP ROADLINES | H27: 46270 | I27: 1 | J27: 1*12000 | K27: =1*12000 -> 12000 | L27: 7.27 | M27: =+K27*L27 -> 87240 | N27: 260100623 | O27: =$O$3-D27 -> 5.5284715 | P27: =$O$3-H27 -> 0.52847153
B29: Total | I29: =SUM(I25:I28) -> 7 | K29: =SUM(K25:K28) -> 29000 | M29: =SUM(M25:M28) -> 210830
B30: OM6005 | C30: 557 | D30: 46265 | E30: 13180 | F30: 46265 | G30: SP ROADLINES | H30: 46270 | I30: 1 | J30: 1*5000 | K30: =1*5000 -> 5000 | L30: 10.9 | M30: =+K30*L30 -> 54500 | N30: 260100623 | O30: =$O$3-D30 -> 5.5284715 | P30: =$O$3-H30 -> 0.52847153
B31: OM6005 | C31: 548 | D31: 46265 | E31: 13180 | F31: 46265 | G31: SP ROADLINES | H31: 46270 | I31: 3 | J31: 3*5000 | K31: =3*5000 -> 15000 | L31: 10.9 | M31: =+K31*L31 -> 163500 | N31: 260100623 | O31: =$O$3-D31 -> 5.5284715 | P31: =$O$3-H31 -> 0.52847153
B33: Total | I33: =SUM(I30:I32) -> 4 | K33: =SUM(K30:K32) -> 20000 | M33: =SUM(M30:M32) -> 218000
B34: IM6005 | C34: 522 | D34: 46255 | E34: 13132 | F34: 46255 | G34: SP ROADLINES | H34: 46260 | I34: =2+1-2 -> 1 | J34: 1*9000 | K34: =2*10000+1*9000-20000 -> 9000 | L34: 8.16 | M34: =+K34*L34 -> 73440 | N34: 260100615 | O34: =$O$3-D34 -> 15.528472 | P34: =$O$3-H34 -> 10.528472
B35: IM6005 | C35: 532 | D35: 46258 | E35: - | F35: 46258 | G35: SP ROADLINES | H35: 46262 | I35: 1 | J35: 1*10000 | K35: =1*10000 -> 10000 | L35: 8.16 | M35: =+K35*L35 -> 81600 | N35: 260100615 | O35: =$O$3-D35 -> 12.528472 | P35: =$O$3-H35 -> 8.5284715
B36: IM6005 | C36: 538 | D36: 46260 | E36: 13158 | F36: 46260 | G36: SP ROADLINES | H36: 46262 | I36: 1 | J36: 1*10000 | K36: =1*10000 -> 10000 | L36: 8.16 | M36: =+K36*L36 -> 81600 | N36: 260100615 | O36: =$O$3-D36 -> 10.528472 | P36: =$O$3-H36 -> 8.5284715
B37: IM6005 | C37: 558 | D37: 46265 | E37: 13180 | F37: 46265 | G37: SP ROADLINES | H37: 46270 | I37: 1 | J37: 1*10000 | K37: =1*10000 -> 10000 | L37: 8.16 | M37: =+K37*L37 -> 81600 | N37: 260100615 | O37: =$O$3-D37 -> 5.5284715 | P37: =$O$3-H37 -> 0.52847153
B38: IM6005 | C38: 549 | D38: 46265 | E38: 13180 | F38: 46265 | G38: SP ROADLINES | H38: 46270 | I38: 1 | J38: 1*10000 | K38: =1*10000 -> 10000 | L38: 8.16 | M38: =+K38*L38 -> 81600 | N38: 260100615 | O38: =$O$3-D38 -> 5.5284715 | P38: =$O$3-H38 -> 0.52847153
B40: Total | I40: =SUM(I34:I39) -> 5 | K40: =SUM(K34:K39) -> 49000 | M40: =SUM(M34:M39) -> 399840
B41: OM6302 | C41: 555 | D41: 46265 | E41: 13180 | F41: 46265 | G41: SP ROADLINES | H41: 46270 | I41: 1 | J41: 1*6000 | K41: =1*6000 -> 6000 | L41: 11.3 | M41: =+K41*L41 -> 67800 | N41: 260101375 | O41: =$O$3-D41 -> 5.5284715 | P41: =$O$3-H41 -> 0.52847153
B42: OM6302 | C42: 550 | D42: 46265 | E42: 13180 | F42: 46265 | G42: SP ROADLINES | H42: 46270 | I42: 2 | J42: 2*6000 | K42: =2*6000 -> 12000 | L42: 11.3 | M42: =+K42*L42 -> 135600 | N42: 260101375 | O42: =$O$3-D42 -> 5.5284715 | P42: =$O$3-H42 -> 0.52847153
B44: Total | I44: =SUM(I41:I43) -> 3 | K44: =SUM(K41:K43) -> 18000 | M44: =SUM(M41:M43) -> 203400
B45: IM6302 | M45: =+K45*L45 -> 0 | N45: 260100623 | O45: =$O$3-D45 -> 46270.528 | P45: =$O$3-H45 -> 46270.528
B47: Total | I47: =SUM(I45:I46) -> 0 | K47: =SUM(K45:K46) -> 0 | M47: =SUM(M45:M46) -> 0
B48: IM6302HSL | C48: 495 | D48: 46246 | E48: 13084 | F48: 46246 | G48: SP ROADLINES | H48: 46252 | I48: 1 | J48: 1*1500 | K48: =1*1500 -> 1500 | L48: 7.82 | M48: =+K48*L48 -> 11730 | N48: 260100623 | O48: =$O$3-D48 -> 24.528472 | P48: =$P$3-H48 -> 18.528472
...

Sheet Summary
B2: Aashita Enter Job Work Stock As on
L3: =+NOW() -> 46270.528
B4: TYPES | C4: Monthly Call off | D4: Opening Bal current month | E4: Rec Qty From Factory in current month | F4: Total Received Qty From Factory | G4: Quntity Lifted by SKF | H4: Balance Qty available in SLN | I4: Call off difference | J4: RING Weight | K4: Balance Weight in KG's | L4: Basic Value | M4: Sep-26 Rec Weight In KG's SLN W/h
B6: OM6004D8 | C6: 0 | D6: 122900 | E6: =F6-D6 -> 0 | F6: =+Receipt!K20 -> 122900 | G6: =+Receipt!R20 -> 0 | H6: =+Receipt!T20 -> 122900 | I6: =G6-C6 -> 0 | J6: 0.034 | K6: =+H6*J6 -> 4178.6 | L6: ='Type Wise Stock'!M20 -> 1232687 | M6: =E6*J6 -> 0
B7: OM6004 | C7: 0 | D7: 0 | E7: =F7-D7 -> 12000 | F7: =+Receipt!K24 -> 12000 | G7: =+Receipt!R24 -> 0 | H7: =+Receipt!T24 -> 12000 | I7: =G7-C7 -> 0 | J7: 0.034 | K7: =+H7*J7 -> 408 | L7: ='Type Wise Stock'!M21 -> 61380 | M7: =E7*J7 -> 408
B8: IM6004 | C8: 0 | D8: 17000 | E8: =F8-D8 -> 12000 | F8: =+Receipt!K29 -> 29000 | G8: =+Receipt!R29 -> 0 | H8: =+Receipt!T29 -> 29000 | I8: =G8-C8 -> 0 | J8: 0.023 | K8: =+H8*J8 -> 667 | L8: ='Type Wise Stock'!M29 -> 210830 | M8: =E8*J8 -> 276
B9: OM6005 | C9: 0 | D9: 0 | E9: =F9-D9 -> 20000 | F9: =+Receipt!K33 -> 20000 | G9: =+Receipt!R33 -> 0 | H9: =+Receipt!T33 -> 20000 | I9: =G9-C9 -> 0 | J9: 0.042 | K9: =+H9*J9 -> 840 | L9: ='Type Wise Stock'!M33 -> 218000 | M9: =E9*J9 -> 840
B10: IM6005 | C10: 0 | D10: 29000 | E10: =F10-D10 -> 20000 | F10: =+Receipt!K40 -> 49000 | G10: =+Receipt!R40 -> 0 | H10: =+Receipt!T40 -> 49000 | I10: =G10-C10 -> 0 | J10: 0.032 | K10: =+H10*J10 -> 1568 | L10: ='Type Wise Stock'!M40 -> 399840 | M10: =E10*J10 -> 640
B11: OM6302 | C11: 0 | D11: 0 | E11: =F11-D11 -> 18000 | F11: =+Receipt!K44 -> 18000 | G11: =+Receipt!R44 -> 0 | H11: =+Receipt!T44 -> 18000 | I11: =G11-C11 -> 0 | J11: 0.045693063 | K11: =+H11*J11 -> 822.47514 | L11: ='Type Wise Stock'!M44 -> 203400 | M11: =E11*J11 -> 822.47514
B12: IM6302 | C12: 0 | D12: 0 | E12: =F12-D12 -> 12000 | F12: =+Receipt!K47 -> 12000 | G12: =+Receipt!R47 -> 12000 | H12: =+Receipt!T47 -> 0 | I12: =G12-C12 -> 12000 | J12: 0.024 | K12: =+H12*J12 -> 0 | L12: ='Type Wise Stock'!M47 -> 0 | M12: =E12*J12 -> 288
B13: IM6302HSL | C13: 0 | D13: 1500 | E13: =F13-D13 -> 0 | F13: =+Receipt!K50 -> 1500 | G13: =+Receipt!R50 -> 0 | H13: =+Receipt!T50 -> 1500 | I13: =G13-C13 -> 0 | J13: 0.024 | K13: =+H13*J13 -> 36 | L13: ='Type Wise Stock'!M50 -> 11730 | M13: =E13*J13 -> 0
B14: OMBB12697 | C14: 0 | D14: 104000 | E14: =F14-D14 -> 2800 | F14: =+Receipt!K66 -> 106800 | G14: =+Receipt!R66 -> 0 | H14: =+Receipt!T66 -> 106800 | I14: =G14-C14 -> 0 | J14: 0.081 | K14: =+H14*J14 -> 8650.8 | L14: ='Type Wise Stock'!M66 -> 2044152 | M14: =E14*J14 -> 226.8
B15: IMBB12697 | C15: 0 | D15: 0 | E15: =F15-D15 -> 0 | F15: =+Receipt!K69 -> 0 | G15: =+Receipt!R69 -> 0 | H15: =+Receipt!T69 -> 0 | I15: =G15-C15 -> 0 | J15: 0.05 | K15: =+H15*J15 -> 0 | L15: ='Type Wise Stock'!M69 -> 0 | M15: =E15*J15 -> 0
B16: OM6305 | C16: 0 | D16: 54000 | E16: =F16-D16 -> 18000 | F16: =+Receipt!K76 -> 72000 | G16: =+Receipt!R76 -> 0 | H16: =+Receipt!T76 -> 72000 | I16: =G16-C16 -> 0 | J16: 0.113 | K16: =+H16*J16 -> 8136 | L16: ='Type Wise Stock'!M76 -> 1838880 | M16: =E16*J16 -> 2034
B17: IM6305 | C17: 0 | D17: 0 | E17: =F17-D17 -> 15000 | F17: =+Receipt!K80 -> 15000 | G17: =+Receipt!R80 -> 0 | H17: =+Receipt!T80 -> 15000 | I17: =G17-C17 -> 0 | J17: 0.063 | K17: =+H17*J17 -> 945 | L17: ='Type Wise Stock'!M80 -> 247050 | M17: =E17*J17 -> 945
B19: Grand Total | C19: =SUM(C6:C18) -> 0 | D19: =SUM(D6:D18) -> 328400 | E19: =SUM(E6:E18) -> 129800 | F19: =SUM(F6:F18) -> 458200 | G19: =SUM(G6:G18) -> 12000 | H19: =SUM(H6:H18) -> 446200 | I19: =SUM(I6:I18) -> 12000 | K19: =SUM(K6:K18) -> 26251.875 | L19: =SUM(L6:L18) -> 6467949 | M19: =SUM(M6:M18) -> 6480.2751
B21: Stock Status | D21: =IF(D19+E19-G19=H19,"STOCK OK", " STOCK NOT MATCHING" ) -> STOCK OK
D23: Material last Received
D24: DC NO | F24: 544-558
D25: DC Date | F25: 46265
D26: Rece Date | F26: 46270
G61: 479 | H61: 45316
G62: 479 | H62: 45316
G63: 480
G64: 480
G65: 480
G66: 480
G67: 480
G68: 481
G69: 481
G70: 481
G71: 481
G72: 481

Sheet Sales Statement
D2: Sales Statement | N2: Supplier: | O2: AASHITA ENTERPRISES
B3: Customer : SKF INDIA LTD. | O3: 149-A,ROAD NO.12,
B4: Bommasandra,Bangalore 561 100. | F4: SKF AUTOMATIVE | O4: JHOTWARA INDUSTRIAL AREA JAIPUR-302012
B5: Month : SEPTEMBER-2026 | F5: SKF INDUSTRIAL | O5: GSTIN : 08AAZPG5776C1Z7
O6: STATE NAME : RAJASTHAN,CODE:08
B7: TYPES | C7: FACTROY DC NO | D7: DC DATE | E7: Received Mode | F7: Customer | G7: W/H INV No | H7: Inv Date | I7: GSP 1 COLLER Set | J7: GSP 2 COLLER Set | K7: QTY | L7: Rate | M7: Basic Value | N7: IGST @ 18% | O7: Inv Value | P7: Dispatch Date | Q7: PO NO | R7: RING WT | S7: GSP 1 COLLER Set Wt | T7: GSP 2 COLLER Set Wt | U7: TOTAL RINGS & GSP WT
B8: IM6302 | C8: 556 | D8: 46260 | E8: SP ROADLINES | F8: SKF AUTOMATIVE | H8: 46270 | I8: 0 | J8: 1 | K8: 12000 | L8: 7.62 | M8: =+L8*K8 -> 91440 | N8: =+M8*18% -> 16459.2 | O8: =+N8+M8 -> 107899.2 | P8: 46270 | Q8: P247245 | R8: 0.024 | S8: 0 | T8: 24 | U8: =+K8*R8+I8*S8+J8*T8 -> 312
I10: =SUM(I8:J9) -> 1 | K10: =SUM(K8:K9) -> 12000 | M10: =SUM(M8:M9) -> 91440 | N10: =SUM(N8:N9) -> 16459.2 | O10: =SUM(O8:O9) -> 107899.2 | U10: =SUM(U8:U9) -> 312
B12: Sales Status | E12: =IF(K10=Summary!G19,"SALES OK", " SALES NOT MATCHING" ) -> SALES OK

Sheet Rejection Details
B2: AASHITA REJECTION Stock As On
Q3: =+NOW() -> 46270.528
B4: SYMBOL | C4: R-INV NO | D4: R-INV DT | E4: R-Challan No | F4: R-Challan Date | G4: TRANSPORTER | H4: E-Sugam No | I4: REC.DATE | J4: QTY | K4: RATE | L4: Basic Value | M4: IGST | N4: INV.VALUE | O4: RING WT | P4: TOTAL WEIGHT | Q4: Age of Days | R4: Remarks
B5: OM6005 | C5: - | D5: - | E5: 1903208 | F5: 45918 | G5: SLN | H5: 1822 2066 0485 | I5: 45924 | J5: =25000-24692 -> 308 | K5: 10.9 | L5: =+J5*K5 -> 3357.2 | M5: =+L5*18% -> 604.296 | N5: =+L5+M5 -> 3961.496 | O5: 0.042 | P5: =+J5*O5 -> 12.936 | Q5: =+$Q$3-I5 -> 346.52847 | R5: 24692 Nos Sent To Skf DcNo- 434 Dt: 27-09-25
B7: Total | J7: =SUM(J5:J6) -> 308 | L7: =SUM(L5:L6) -> 3357.2 | M7: =SUM(M5:M6) -> 604.296 | N7: =SUM(N5:N6) -> 3961.496 | P7: =SUM(P5:P6) -> 12.936
B8: OM6305 | C8: BGWVRD0148 | D8: 45864 | E8: 1902991 | F8: 45855 | G8: SLN | H8: - | I8: 45874 | J8: 1167 | K8: 25.91 | L8: =+J8*K8 -> 30236.97 | M8: =+L8*18% -> 5442.6546 | N8: =+L8+M8 -> 35679.625 | O8: 0.113 | P8: =+J8*O8 -> 131.871 | Q8: =+$Q$3-I8 -> 396.52847
B10: Total | J10: =SUM(J8:J9) -> 1167 | L10: =SUM(L8:L9) -> 30236.97 | M10: =SUM(M8:M9) -> 5442.6546 | N10: =SUM(N8:N9) -> 35679.625 | P10: =SUM(P8:P9) -> 131.871
B11: OM6302 | C11: BGWVRD0451 | D11: 45993 | E11: 1903304 | F11: 45987 | G11: SLN | H11: 6120 1478 5969 | I11: 45994 | J11: =46500-24000-16700 -> 5800 | K11: 11.3 | L11: =+J11*K11 -> 65540 | M11: =+L11*18% -> 11797.2 | N11: =+L11+M11 -> 77337.2 | O11: 0.045693063 | P11: =+J11*O11 -> 265.01977 | Q11: =+$Q$3-I11 -> 276.52847 | R11: ( 4*6000=24000 Fresh Dc Rece Dc No- 670 ( 31.12.2025) TO ( 2*6000+1*4700=16700 Fresh Dc Rece Dc No- 726 ( 10.01.2026)
B12: OM6302 | C12: BGWVRD0474 | D12: 46003 | E12: 1903341 | F12: 46016 | G12: SLN | H12: 1622 9046 3892 | I12: 46004 | J12: 6000 | K12: 11.3 | L12: =+J12*K12 -> 67800 | M12: =+L12*18% -> 12204 | N12: =+L12+M12 -> 80004 | O12: 0.045693063 | P12: =+J12*O12 -> 274.15838 | Q12: =+$Q$3-I12 -> 266.52847 | R12: 1*6000 Pallete
B14: Total | J14: =SUM(J11:J13) -> 11800 | L14: =SUM(L11:L13) -> 133340 | M14: =SUM(M11:M13) -> 24001.2 | N14: =SUM(N11:N13) -> 157341.2 | P14: =SUM(P11:P13) -> 539.17815
B15: OM6005 | C15: - | D15: - | E15: 1903208 | F15: 45918 | G15: SLN | H15: 1822 2066 0485 | I15: 45924 | J15: =25000-24692 -> 308 | K15: 10.9 | L15: =+J15*K15 -> 3357.2 | M15: =+L15*18% -> 604.296 | N15: =+L15+M15 -> 3961.496 | O15: 0.042 | P15: =+J15*O15 -> 12.936 | Q15: =+$Q$3-I15 -> 346.52847 | R15: 24692 Nos Sent To Skf DcNo- 434 Dt: 27-09-25
B17: Total | J17: =SUM(J15:J16) -> 308 | L17: =SUM(L15:L16) -> 3357.2 | M17: =SUM(M15:M16) -> 604.296 | N17: =SUM(N15:N16) -> 3961.496 | P17: =SUM(P15:P16) -> 12.936
B18: OM6305 | C18: BGWVRD0148 | D18: 45864 | E18: 1902991 | F18: 45855 | G18: SLN | H18: - | I18: 45874 | J18: 1167 | K18: 25.91 | L18: =+J18*K18 -> 30236.97 | M18: =+L18*18% -> 5442.6546 | N18: =+L18+M18 -> 35679.625 | O18: 0.113 | P18: =+J18*O18 -> 131.871 | Q18: =+$Q$3-I18 -> 396.52847
B20: Total | J20: =SUM(J18:J19) -> 1167 | L20: =SUM(L18:L19) -> 30236.97 | M20: =SUM(M18:M19) -> 5442.6546 | N20: =SUM(N18:N19) -> 35679.625 | P20: =SUM(P18:P19) -> 131.871
B21: IM6302 | C21: BGWVRD0507 | D21: 46014 | E21: 1903367 | F21: 46011 | G21: SLN | H21: 1123 0191 3504 | I21: 46017 | J21: =60000-24000-34490 -> 1510 | K21: 7.52 | L21: =+J21*K21 -> 11355.2 | M21: =+L21*18% -> 2043.936 | N21: =+L21+M21 -> 13399.136 | O21: 0.024 | P21: =+J21*O21 -> 36.24 | Q21: =+$Q$3-I21 -> 253.52847 | R21: ( 2*12000=24000 Fresh Dc Rece Dc No- 778 ( 27.01.2026) DC No 871 -25.02.2026 (2*12000+1*10490 =34490 NOS)
B23: Total | J23: =SUM(J21:J22) -> 1510 | L23: =SUM(L21:L22) -> 11355.2 | M23: =SUM(M21:M22) -> 2043.936 | N23: =SUM(N21:N22) -> 13399.136 | P23: =SUM(P21:P22) -> 36.24
B24: OM6005 | C24: - | D24: - | E24: 1903208 | F24: 45918 | G24: SLN | H24: 1822 2066 0485 | I24: 45924 | J24: =25000-24692 -> 308 | K24: 10.9 | L24: =+J24*K24 -> 3357.2 | M24: =+L24*18% -> 604.296 | N24: =+L24+M24 -> 3961.496 | O24: 0.042 | P24: =+J24*O24 -> 12.936 | Q24: =+$Q$3-I24 -> 346.52847 | R24: 24692 Nos Sent To Skf DcNo- 434 Dt: 27-09-25
B26: Total | J26: =SUM(J24:J25) -> 308 | L26: =SUM(L24:L25) -> 3357.2 | M26: =SUM(M24:M25) -> 604.296 | N26: =SUM(N24:N25) -> 3961.496 | P26: =SUM(P24:P25) -> 12.936
B27: OM6305 | C27: BGWVRD0148 | D27: 45864 | E27: 1902991 | F27: 45855 | G27: SLN | H27: - | I27: 45874 | J27: 1167 | K27: 25.91 | L27: =+J27*K27 -> 30236.97 | M27: =+L27*18% -> 5442.6546 | N27: =+L27+M27 -> 35679.625 | O27: 0.113 | P27: =+J27*O27 -> 131.871 | Q27: =+$Q$3-I27 -> 396.52847
B29: Total | J29: =SUM(J27:J28) -> 1167 | L29: =SUM(L27:L28) -> 30236.97 | M29: =SUM(M27:M28) -> 5442.6546 | N29: =SUM(N27:N28) -> 35679.625 | P29: =SUM(P27:P28) -> 131.871
B30: OM6305 | C30: KWHVR0068 | D30: 45980 | G30: SLN | H30: 1722 9371 3627 | I30: 46008 | J30: 1184 | K30: 25.54 | L30: =+J30*K30 -> 30239.36 | M30: =+L30*18% -> 5443.0848 | N30: =+L30+M30 -> 35682.445 | O30: 0.113 | P30: =+J30*O30 -> 133.792 | Q30: =+$Q$3-I30 -> 262.52847 | R30: 1*1184 Pallete
B32: Total | J32: =SUM(J30:J31) -> 1184 | L32: =SUM(L30:L31) -> 30239.36 | M32: =SUM(M30:M31) -> 5443.0848 | N32: =SUM(N30:N31) -> 35682.445 | P32: =SUM(P30:P31) -> 133.792
B33: IM6004 | C33: BGWVRD0694 | D33: 46162 | E33: 1903611 | F33: 46154 | G33: SLN | H33: - | I33: 46177 | J33: 2459 | K33: 7.27 | L33: =+J33*K33 -> 17876.93 | M33: =+L33*18% -> 3217.8474 | N33: =+L33+M33 -> 21094.777 | O33: 0.023 | P33: =+J33*O33 -> 56.557 | Q33: =+$Q$3-I33 -> 93.528472
B35: Total | J35: =SUM(J33:J34) -> 2459 | L35: =SUM(L33:L34) -> 17876.93 | M35: =SUM(M33:M34) -> 3217.8474 | N35: =SUM(N33:N34) -> 21094.777 | P35: =SUM(P33:P34) -> 56.557
